Workbook

Sheet RESUMEN
B4: INGRESOS
B5: ENERO | C5: FEBRERO | D5: MARZO | E5: ABRIL | F5: MAYO | G5: JUNIO | H5: JULIO | I5: AGOSTO | J5: SEPTIEMBRE | K5: OCTUBRE | L5: NOVIEMBRE | M5: DICIEMBRE | N5: TOTAL ANUAL
A6: SUELDO | B6: =SUELDO!B89 -> 1500000 | C6: =SUELDO!C89 -> 1800000 | D6: =SUELDO!D89 -> 1800000 | E6: =SUELDO!E89 -> 1880000 | F6: =SUELDO!F89 -> 0 | G6: =SUELDO!G89 -> 0 | H6: =SUELDO!H89 -> 0 | I6: =SUELDO!I89 -> 0 | ... M6: =SUELDO!M89 -> 0 | N6: =SUM(B6:M6) -> 6980000
A7: INVERSION | B7: =INVERSION!B89 -> 0 | C7: =INVERSION!C89 -> 0 | D7: =INVERSION!D89 -> 0 | E7: =INVERSION!E89 -> 0 | F7: =INVERSION!F89 -> 0 | G7: =INVERSION!G89 -> 0 | H7: =INVERSION!H89 -> 0 | I7: =INVERSION!I89 -> 0 | ... M7: =INVERSION!M89 -> 0 | N7: =SUM(B7:M7) -> 0
A8: ENG | B8: =ENG!B89 -> 0 | C8: =ENG!C89 -> 0 | D8: =ENG!D89 -> 0 | E8: =ENG!E89 -> 0 | F8: =ENG!F89 -> 0 | G8: =ENG!G89 -> 0 | H8: =ENG!H89 -> 0 | I8: =ENG!I89 -> 0 | ... M8: =ENG!M89 -> 0 | N8: =SUM(B8:M8) -> 0
A9: DOLARES | B9: =DOLARES!B89 -> 0 | C9: =DOLARES!C89 -> 0 | D9: =DOLARES!D89 -> 0 | E9: =DOLARES!E89 -> 0 | F9: =DOLARES!F89 -> 0 | G9: =DOLARES!G89 -> 0 | H9: =DOLARES!H89 -> 0 | I9: =DOLARES!I89 -> 0 | ... M9: =DOLARES!M89 -> 0 | N9: =SUM(B9:M9) -> 0
A10: FERIADOS | B10: =FERIADOS!B89 -> 0 | C10: =FERIADOS!C89 -> 0 | D10: =FERIADOS!D89 -> 0 | E10: =FERIADOS!E89 -> 0 | F10: =FERIADOS!F89 -> 0 | G10: =FERIADOS!G89 -> 0 | H10: =FERIADOS!H89 -> 0 | I10: =FERIADOS!I89 -> 0 | ... M10: =FERIADOS!M89 -> 0 | N10: =SUM(B10:M10) -> 0
A11: PREMIOS CMV | B11: ='PREMIO CMV'!B89 -> 0 | C11: ='PREMIO CMV'!C89 -> 0 | D11: ='PREMIO CMV'!D89 -> 0 | E11: ='PREMIO CMV'!E89 -> 0 | F11: ='PREMIO CMV'!F89 -> 0 | G11: ='PREMIO CMV'!G89 -> 0 | H11: ='PREMIO CMV'!H89 -> 0 | I11: ='PREMIO CMV'!I89 -> 0 | ... M11: ='PREMIO CMV'!M89 -> 0 | N11: =SUM(B11:M11) -> 0
A12: OTROS | B12: =OTROS!B89 -> 0 | C12: =OTROS!C89 -> 0 | D12: =OTROS!D89 -> 0 | E12: =OTROS!E89 -> 0 | F12: =OTROS!F89 -> 0 | G12: =OTROS!G89 -> 0 | H12: =OTROS!H89 -> 0 | I12: =OTROS!I89 -> 0 | ... M12: =OTROS!M89 -> 0 | N12: =SUM(B12:M12) -> 0
A13: TOTAL INGRESOS | B13: =SUM(B6:B12) -> 1500000 | C13: =SUM(C6:C12) -> 1800000 | D13: =SUM(D6:D12) -> 1800000 | E13: =SUM(E6:E12) -> 1880000 | F13: =SUM(F6:F12) -> 0 | G13: =SUM(G6:G12) -> 0 | H13: =SUM(H6:H12) -> 0 | I13: =SUM(I6:I12) -> 0 | ... M13: =SUM(M6:M12) -> 0 | N13: =SUM(B13:M13) -> 6980000
B15: EGRESOS
B16: ENERO | C16: FEBRERO | D16: MARZO | E16: ABRIL | F16: MAYO | G16: JUNIO | H16: JULIO | I16: AGOSTO | J16: SEPTIEMBRE | K16: OCTUBRE | L16: NOVIEMBRE | M16: DICIEMBRE | N16: TOTAL ANUAL
A17: ALQUILER | B17: =ALQUILER!B89 -> 392352 | C17: =ALQUILER!C89 -> 392352 | D17: =ALQUILER!D89 -> 0 | E17: =ALQUILER!E89 -> 0 | F17: =ALQUILER!F89 -> 0 | G17: =ALQUILER!G89 -> 0 | H17: =ALQUILER!H89 -> 0 | I17: =ALQUILER!I89 -> 0 | ... M17: =ALQUILER!M89 -> 0 | N17: =SUM(B17:M17) -> 784704
A18: COMIDA | B18: =COMIDA!B121 -> 200000 | C18: =COMIDA!C121 -> 0 | D18: =COMIDA!D121 -> 197123.25 | E18: =COMIDA!E121 -> 278490 | F18: =COMIDA!F121 -> 141388.76 | G18: =COMIDA!G121 -> 231889.92 | H18: =COMIDA!H121 -> 0 | I18: =COMIDA!I121 -> 139143.06 | ... M18: =COMIDA!M121 -> 0 | N18: =SUM(B18:M18) -> 1580563.9
A19: COMIDA AFUERA | B19: ='COMIDA AFUERA'!B121 -> 0 | C19: ='COMIDA AFUERA'!C121 -> 0 | D19: ='COMIDA AFUERA'!D121 -> 10000 | E19: ='COMIDA AFUERA'!E121 -> 0 | F19: ='COMIDA AFUERA'!F121 -> 0 | G19: ='COMIDA AFUERA'!G121 -> 0 | H19: ='COMIDA AFUERA'!H121 -> 0 | I19: ='COMIDA AFUERA'!I121 -> 0 | ... M19: ='COMIDA AFUERA'!M121 -> 0 | N19: =SUM(B19:M19) -> 10000
A20: SUBE | B20: =SUBE!B121 -> 28700 | C20: =SUBE!C121 -> 32700 | D20: =SUBE!D121 -> 44350 | E20: =SUBE!E121 -> 22700 | F20: =SUBE!F121 -> 12700 | G20: =SUBE!G121 -> 12700 | H20: =SUBE!H121 -> 0 | I20: =SUBE!I121 -> 63358 | ... M20: =SUBE!M121 -> 0 | N20: =SUM(B20:M20) -> 292208
A21: IMPUESTOS | B21: =IMPUESTOS!B121 -> 0 | C21: =IMPUESTOS!C121 -> 0 | D21: =IMPUESTOS!D121 -> 0 | E21: =IMPUESTOS!E121 -> 64510 | F21: =IMPUESTOS!F121 -> 75832.48 | G21: =IMPUESTOS!G121 -> 71670 | H21: =IMPUESTOS!H121 -> 0 | I21: =IMPUESTOS!I121 -> 144003 | ... M21: =IMPUESTOS!M121 -> 0 | N21: =SUM(B21:M21) -> 669295.48
A22: TELEFONIA | B22: =TELEFONIA!B89 -> 12000 | C22: =TELEFONIA!C89 -> 12000 | D22: =TELEFONIA!D89 -> 14000 | E22: =TELEFONIA!E89 -> 18200 | F22: =TELEFONIA!F89 -> 0 | G22: =TELEFONIA!G89 -> 0 | H22: =TELEFONIA!H89 -> 0 | I22: =TELEFONIA!I89 -> 13000 | ... M22: =TELEFONIA!M89 -> 0 | N22: =SUM(B22:M22) -> 97200
A23: DIMITRI | B23: =DIMITRI!B121 -> 60000 | C23: =DIMITRI!C121 -> 60000 | D23: =DIMITRI!D121 -> 65000 | E23: =DIMITRI!E121 -> 116500 | F23: =DIMITRI!F121 -> 0 | G23: =DIMITRI!G121 -> 0 | H23: =DIMITRI!H121 -> 0 | I23: =DIMITRI!I121 -> 0 | ... M23: =DIMITRI!M121 -> 0 | N23: =SUM(B23:M23) -> 333000
A24: ROPA | B24: =ROPA!B89 -> 0 | C24: =ROPA!C89 -> 0 | D24: =ROPA!D89 -> 0 | E24: =ROPA!E89 -> 0 | F24: =ROPA!F89 -> 0 | G24: =ROPA!G89 -> 0 | H24: =ROPA!H89 -> 0 | I24: =ROPA!I89 -> 0 | ... M24: =ROPA!M89 -> 0 | N24: =SUM(B24:M24) -> 0
A25: EQUIPAMIENTO | B25: =EQUIPAMIENTO!B89 -> 0 | C25: =EQUIPAMIENTO!C89 -> 0 | D25: =EQUIPAMIENTO!D89 -> 0 | E25: =EQUIPAMIENTO!E89 -> 199000 | F25: =EQUIPAMIENTO!F89 -> 90000 | G25: =EQUIPAMIENTO!G89 -> 43500 | H25: =EQUIPAMIENTO!H89 -> 0 | I25: =EQUIPAMIENTO!I89 -> 0 | ... M25: =EQUIPAMIENTO!M89 -> 0 | N25: =SUM(B25:M25) -> 433580
A26: LIMP & HIGUIENE | B26: ='LIMP &HIGUIENE'!B89 -> 0 | C26: ='LIMP &HIGUIENE'!C89 -> 0 | D26: ='LIMP &HIGUIENE'!D89 -> 12000 | E26: ='LIMP &HIGUIENE'!E89 -> 12000 | F26: ='LIMP &HIGUIENE'!F89 -> 33000 | G26: ='LIMP &HIGUIENE'!G89 -> 25503 | H26: ='LIMP &HIGUIENE'!H89 -> 0 | I26: ='LIMP &HIGUIENE'!I89 -> 0 | ... M26: ='LIMP &HIGUIENE'!M89 -> 0 | N26: =SUM(B26:M26) -> 82503
A27: PSICOLOGO | B27: =PSICOLOGO!B89 -> 0 | C27: =PSICOLOGO!C89 -> 0 | D27: =PSICOLOGO!D89 -> 0 | E27: =PSICOLOGO!E89 -> 0 | F27: =PSICOLOGO!F89 -> 0 | G27: =PSICOLOGO!G89 -> 0 | H27: =PSICOLOGO!H89 -> 0 | I27: =PSICOLOGO!I89 -> 0 | ... M27: =PSICOLOGO!M89 -> 0 | N27: =SUM(B27:M27) -> 0
A28: YOGA | B28: =YOGA!B89 -> 0 | C28: =YOGA!C89 -> 0 | D28: =YOGA!D89 -> 0 | E28: =YOGA!E89 -> 0 | F28: =YOGA!F89 -> 0 | G28: =YOGA!G89 -> 0 | H28: =YOGA!H89 -> 0 | I28: =YOGA!I89 -> 0 | ... M28: =YOGA!M89 -> 0 | N28: =SUM(B28:M28) -> 0
A29: DEPORTE | B29: =DEPORTE!B89 -> 155000 | C29: =DEPORTE!C89 -> 155000 | D29: =DEPORTE!D89 -> 140000 | E29: =DEPORTE!E89 -> 109000 | F29: =DEPORTE!F89 -> 0 | G29: =DEPORTE!G89 -> 200000 | H29: =DEPORTE!H89 -> 0 | I29: =DEPORTE!I89 -> 170000 | ... M29: =DEPORTE!M89 -> 0 | N29: =SUM(B29:M29) -> 929000
A30: EDUCACION | B30: =EDUCACION!B89 -> 0 | C30: =EDUCACION!C89 -> 0 | D30: =EDUCACION!D89 -> 0 | E30: =EDUCACION!E89 -> 0 | F30: =EDUCACION!F89 -> 0 | G30: =EDUCACION!G89 -> 0 | H30: =EDUCACION!H89 -> 0 | I30: =EDUCACION!I89 -> 0 | ... M30: =EDUCACION!M89 -> 0 | N30: =SUM(B30:M30) -> 0
A31: AYUDA A OTROS | B31: ='AYUDA A OTROS'!B121 -> 0 | C31: ='AYUDA A OTROS'!C121 -> 0 | D31: ='AYUDA A OTROS'!D121 -> 0 | E31: ='AYUDA A OTROS'!E121 -> 0 | F31: ='AYUDA A OTROS'!F121 -> 0 | G31: ='AYUDA A OTROS'!G121 -> 0 | H31: ='AYUDA A OTROS'!H121 -> 0 | I31: ='AYUDA A OTROS'!I121 -> 0 | ... M31: ='AYUDA A OTROS'!M121 -> 0 | N31: =SUM(B31:M31) -> 0
A32: MEDICOS | B32: =MEDICOS!B89 -> 0 | C32: =MEDICOS!C89 -> 0 | D32: =MEDICOS!D89 -> 0 | E32: =MEDICOS!E89 -> 13770 | F32: =MEDICOS!F89 -> 0 | G32: =MEDICOS!G89 -> 0 | H32: =MEDICOS!H89 -> 0 | I32: =MEDICOS!I89 -> 22000 | ... M32: =MEDICOS!M89 -> 0 | N32: =SUM(B32:M32) -> 67770
A33: SALIDA CHICAS | B33: ='SALIDA CHICAS'!B89 -> 0 | C33: ='SALIDA CHICAS'!C89 -> 0 | D33: ='SALIDA CHICAS'!D89 -> 0 | E33: ='SALIDA CHICAS'!E89 -> 205674 | F33: ='SALIDA CHICAS'!F89 -> 0 | G33: ='SALIDA CHICAS'!G89 -> 0 | H33: ='SALIDA CHICAS'!H89 -> 0 | I33: ='SALIDA CHICAS'!I89 -> 0 | ... M33: ='SALIDA CHICAS'!M89 -> 0 | N33: =SUM(B33:M33) -> 205674
A34: SALIDA AMIGOS | B34: ='SALIDA AMIGOS'!B89 -> 0 | C34: ='SALIDA AMIGOS'!C89 -> 0 | D34: ='SALIDA AMIGOS'!D89 -> 0 | E34: ='SALIDA AMIGOS'!E89 -> 0 | F34: ='SALIDA AMIGOS'!F89 -> 0 | G34: ='SALIDA AMIGOS'!G89 -> 0 | H34: ='SALIDA AMIGOS'!H89 -> 0 | I34: ='SALIDA AMIGOS'!I89 -> 0 | ... M34: ='SALIDA AMIGOS'!M89 -> 0 | N34: =SUM(B34:M34) -> 0
A35: APPS | B35: =APPS!B89 -> 25840 | C35: =APPS!C89 -> 25840 | D35: =APPS!D89 -> 25840 | E35: =APPS!E89 -> 38125 | F35: =APPS!F89 -> 12285 | G35: =APPS!G89 -> 31000 | H35: =APPS!H89 -> 0 | I35: =APPS!I89 -> 0 | ... M35: =APPS!M89 -> 0 | N35: =SUM(B35:M35) -> 158930
A36: TAXI SALIDAS | B36: ='TAXI SALIDAS'!B121 -> 0 | C36: ='TAXI SALIDAS'!C121 -> 0 | D36: ='TAXI SALIDAS'!D121 -> 0 | E36: ='TAXI SALIDAS'!E121 -> 0 | F36: ='TAXI SALIDAS'!F121 -> 0 | G36: ='TAXI SALIDAS'!G121 -> 0 | H36: ='TAXI SALIDAS'!H121 -> 0 | I36: ='TAXI SALIDAS'!I121 -> 0 | ... M36: ='TAXI SALIDAS'!M121 -> 0 | N36: =SUM(B36:M36) -> 0
A37: VACACIONES | B37: =VACACIONES!B89 -> 0 | C37: =VACACIONES!C89 -> 0 | D37: =VACACIONES!D89 -> 0 | E37: =VACACIONES!E89 -> 0 | F37: =VACACIONES!F89 -> 0 | G37: =VACACIONES!G89 -> 0 | H37: =VACACIONES!H89 -> 0 | I37: =VACACIONES!I89 -> 0 | ... M37: =VACACIONES!M89 -> 0 | N37: =SUM(B37:M37) -> 0
C38: 0 | N38: =SUM(B38:M38) -> 0
A39: TOTAL EGRESOS | B39: =SUM(B17:B38) -> 873892 | C39: =SUM(C17:C38) -> 677892 | D39: =SUM(D17:D38) -> 508313.25 | E39: =SUM(E17:E38) -> 1077969 | F39: =SUM(F17:F38) -> 365206.24 | G39: =SUM(G17:G38) -> 616262.92 | H39: =SUM(H17:H38) -> 0 | I39: =SUM(I17:I38) -> 551504.06 | ... N39: =SUM(N17:N38) -> 5644428.4
A40: SALDO | B40: =B13-B39 -> 626108 | C40: =C13-C39 -> 1122108 | D40: =D13-D39 -> 1291686.8 | E40: =E13-E39 -> 802031 | F40: =F13-F39 -> -365206.24 | G40: =G13-G39 -> -616262.92 | H40: =H13-H39 -> 0 | I40: =I13-I39 -> -551504.06 | ... N40: =N13-N39 -> 1335571.6
B42: RECUENTO CAJA
B43: ENERO | C43: FEBRERO | D43: MARZO | E43: ABRIL | F43: MAYO | G43: JUNIO | H43: JULIO | I43: AGOSTO | J43: SEPTIEMBRE | K43: OCTUBRE | L43: NOVIEMBRE | M43: DICIEMBRE
A44: EFECTIVO | M44: 150000
A45: MERCADO PAGO | M45: 67738
...

Sheet SUELDO
A1: ITEM | B1: ENERO | C1: FEBRERO | D1: MARZO | E1: ABRIL | F1: MAYO | G1: JUNIO | H1: JULIO | I1: AGOSTO | J1: SEPTIEMBRE | K1: OCTUBRE | L1: NOVIEMBRE | M1: DICIEMBRE
A2: SUELDO | B2: 1500000 | C2: =1800000 -> 1800000 | D2: =1800000 -> 1800000 | E2: =1800000+80000 -> 1880000
A89: TOTAL | B89: =+SUM(B2:B88) -> 1500000 | C89: =+SUM(C2:C88) -> 1800000 | D89: =+SUM(D2:D88) -> 1800000 | E89: =+SUM(E2:E88) -> 1880000 | F89: =+SUM(F2:F88) -> 0 | G89: =+SUM(G2:G88) -> 0 | H89: =+SUM(H2:H88) -> 0 | I89: =+SUM(I2:I88) -> 0 | ... M89: =+SUM(M2:M88) -> 0

Sheet INVERSION
A1: ITEM | B1: ENERO | C1: FEBRERO | D1: MARZO | E1: ABRIL | F1: MAYO | G1: JUNIO | H1: JULIO | I1: AGOSTO | J1: SEPTIEMBRE | K1: OCTUBRE | L1: NOVIEMBRE | M1: DICIEMBRE
A89: TOTAL | B89: =+SUM(B2:B88) -> 0 | C89: =+SUM(C2:C88) -> 0 | D89: =+SUM(D2:D88) -> 0 | E89: =+SUM(E2:E88) -> 0 | F89: =+SUM(F2:F88) -> 0 | G89: =+SUM(G2:G88) -> 0 | H89: =+SUM(H2:H88) -> 0 | I89: =+SUM(I2:I88) -> 0 | ... M89: =+SUM(M2:M88) -> 0

Sheet ENG
A1: ITEM | B1: ENERO | C1: FEBRERO | D1: MARZO | E1: ABRIL | F1: MAYO | G1: JUNIO | H1: JULIO | I1: AGOSTO | J1: SEPTIEMBRE | K1: OCTUBRE | L1: NOVIEMBRE | M1: DICIEMBRE
A89: TOTAL | B89: =+SUM(B2:B88) -> 0 | C89: =+SUM(C2:C88) -> 0 | D89: =+SUM(D2:D88) -> 0 | E89: =+SUM(E2:E88) -> 0 | F89: =+SUM(F2:F88) -> 0 | G89: =+SUM(G2:G88) -> 0 | H89: =+SUM(H2:H88) -> 0 | I89: =+SUM(I2:I88) -> 0 | ... M89: =+SUM(M2:M88) -> 0

Sheet DOLARES
A1: ITEM | B1: ENERO | C1: FEBRERO | D1: MARZO | E1: ABRIL | F1: MAYO | G1: JUNIO | H1: JULIO | I1: AGOSTO | J1: SEPTIEMBRE | K1: OCTUBRE | L1: NOVIEMBRE | M1: DICIEMBRE
A89: TOTAL | B89: =+SUM(B2:B88) -> 0 | C89: =+SUM(C2:C88) -> 0 | D89: =+SUM(D2:D88) -> 0 | E89: =+SUM(E2:E88) -> 0 | F89: =+SUM(F2:F88) -> 0 | G89: =+SUM(G2:G88) -> 0 | H89: =+SUM(H2:H88) -> 0 | I89: =+SUM(I2:I88) -> 0 | ... M89: =+SUM(M2:M88) -> 0

Sheet FERIADOS
A1: ITEM | B1: ENERO | C1: FEBRERO | D1: MARZO | E1: ABRIL | F1: MAYO | G1: JUNIO | H1: JULIO | I1: AGOSTO | J1: SEPTIEMBRE | K1: OCTUBRE | L1: NOVIEMBRE | M1: DICIEMBRE
A89: TOTAL | B89: =+SUM(B2:B88) -> 0 | C89: =+SUM(C2:C88) -> 0 | D89: =+SUM(D2:D88) -> 0 | E89: =+SUM(E2:E88) -> 0 | F89: =+SUM(F2:F88) -> 0 | G89: =+SUM(G2:G88) -> 0 | H89: =+SUM(H2:H88) -> 0 | I89: =+SUM(I2:I88) -> 0 | ... M89: =+SUM(M2:M88) -> 0

Sheet PREMIO CMV
A1: ITEM | B1: ENERO | C1: FEBRERO | D1: MARZO | E1: ABRIL | F1: MAYO | G1: JUNIO | H1: JULIO | I1: AGOSTO | J1: SEPTIEMBRE | K1: OCTUBRE | L1: NOVIEMBRE | M1: DICIEMBRE
A89: TOTAL | B89: =+SUM(B2:B88) -> 0 | C89: =+SUM(C2:C88) -> 0 | D89: =+SUM(D2:D88) -> 0 | E89: =+SUM(E2:E88) -> 0 | F89: =+SUM(F2:F88) -> 0 | G89: =+SUM(G2:G88) -> 0 | H89: =+SUM(H2:H88) -> 0 | I89: =+SUM(I2:I88) -> 0 | ... M89: =+SUM(M2:M88) -> 0

Sheet OTROS
A1: ITEM | B1: ENERO | C1: FEBRERO | D1: MARZO | E1: ABRIL | F1: MAYO | G1: JUNIO | H1: JULIO | I1: AGOSTO | J1: SEPTIEMBRE | K1: OCTUBRE | L1: NOVIEMBRE | M1: DICIEMBRE
A89: TOTAL | B89: =+SUM(B2:B88) -> 0 | C89: =+SUM(C2:C88) -> 0 | D89: =+SUM(D2:D88) -> 0 | E89: =+SUM(E2:E88) -> 0 | F89: =+SUM(F2:F88) -> 0 | G89: =+SUM(G2:G88) -> 0 | H89: =+SUM(H2:H88) -> 0 | I89: =+SUM(I2:I88) -> 0 | ... M89: =+SUM(M2:M88) -> 0

Sheet ALQUILER
A1: ITEM | B1: ENERO | C1: FEBRERO | D1: MARZO | E1: ABRIL | F1: MAYO | G1: JUNIO | H1: JULIO | I1: AGOSTO | J1: SEPTIEMBRE | K1: OCTUBRE | L1: NOVIEMBRE | M1: DICIEMBRE
A2: ALQUILER | B2: 392352 | C2: 392352
A89: TOTAL | B89: =+SUM(B2:B88) -> 392352 | C89: =+SUM(C2:C88) -> 392352 | D89: =+SUM(D2:D88) -> 0 | E89: =+SUM(E2:E88) -> 0 | F89: =+SUM(F2:F88) -> 0 | G89: =+SUM(G2:G88) -> 0 | H89: =+SUM(H2:H88) -> 0 | I89: =+SUM(I2:I88) -> 0 | ... M89: =+SUM(M2:M88) -> 0

Sheet COMIDA
A1: ITEM | B1: ENERO | C1: FEBRERO | D1: MARZO | E1: ABRIL | F1: MAYO | G1: JUNIO | H1: JULIO | I1: AGOSTO | J1: SEPTIEMBRE | K1: OCTUBRE | L1: NOVIEMBRE | M1: DICIEMBRE
A2: COMIDA | B2: =200000 -> 200000 | F2: 10000
A3: PROTEINAS+ VITAMINAS+ PREENTRENO | D3: 107970.5 | F3: 40000
A4: COMIDA | D4: =7040.75+7780+24018+5119+11395+12900+12900+8000 -> 89152.75
A5: COMIDA | E5: =12000+22000+13000 -> 47000
A6: COMIDA | E6: =15000+23200+23500 -> 61700
A7: COMIDA | E7: =24000+25000+30000 -> 79000
A8: COMIDA | E8: =20700+5000+7090+16000+6000 -> 54790
A9: COMIDA | E9: 36000
A10: COMIDA | F10: 19300
A11: COMIDA | F11: 20000
A12: COMIDA | F12: =16116.55+6500+6300+23172.21 -> 52088.76
A13: COMIDA | G13: 9169.92
A14: COMIDA | G14: 20000
A15: COMIDA | G15: 26500
A16: COMIDA | G16: =9500+13000+29000+6000+5000+16000+23000+11500 -> 113000
A17: COMIDA | G17: =13800+6520+7900+11000+13000+11000 -> 63220
A18: COMIDA 12-08 | I18: 15094
A19: 45882 | I19: 11471.6
A20: 45883 | I20: 10000
A21: 45886 | I21: 17213.7
A22: 45895 | I22: =450+1500+15013+10005+14067+7109+2500+5900+2000+12600 -> 71144
A23: 45898 | I23: =6607+7612.76 -> 14219.76
A24: 45901 | J24: 17852
A25: COMIDA | J25: =5300+8930 -> 14230
A26: COMIDA | J26: 20754.2
A27: COMIDA | J27: =13122+8643+2720+6815.25+3600+9100+8100+5500 -> 57600.25
A28: COMIDA | J28: =15500+16200+4500+1750+9070+5500+8800+8500+5900+5900+8000+10000 -> 99620
A29: COMIDA | K29: =68000+9000+1200+6600+2500+6700+1500+9500+600+10000+2400+9800+3000 -> 130800
K30: =10400+14300+1200 -> 25900
L31: =12772.5 -> 12772.5
L32: =13000 -> 13000
A121: TOTAL | B121: =+SUM(B2:B120) -> 200000 | C121: =+SUM(C2:C120) -> 0 | D121: =+SUM(D2:D120) -> 197123.25 | E121: =+SUM(E2:E120) -> 278490 | F121: =+SUM(F2:F120) -> 141388.76 | G121: =+SUM(G2:G120) -> 231889.92 | H121: =+SUM(H2:H120) -> 0 | I121: =+SUM(I2:I120) -> 139143.06 | ... M121: =+SUM(M2:M120) -> 0

Sheet COMIDA AFUERA
A1: ITEM | B1: ENERO | C1: FEBRERO | D1: MARZO | E1: ABRIL | F1: MAYO | G1: JUNIO | H1: JULIO | I1: AGOSTO | J1: SEPTIEMBRE | K1: OCTUBRE | L1: NOVIEMBRE | M1: DICIEMBRE
A2: COMIDA AISHA | D2: 10000
A121: TOTAL | B121: =+SUM(B2:B120) -> 0 | C121: =+SUM(C2:C120) -> 0 | D121: =+SUM(D2:D120) -> 10000 | E121: =+SUM(E2:E120) -> 0 | F121: =+SUM(F2:F120) -> 0 | G121: =+SUM(G2:G120) -> 0 | H121: =+SUM(H2:H120) -> 0 | I121: =+SUM(I2:I120) -> 0 | ... M121: =+SUM(M2:M120) -> 0

Sheet SUBE
A1: ITEM | B1: ENERO | C1: FEBRERO | D1: MARZO | E1: ABRIL | F1: MAYO | G1: JUNIO | H1: JULIO | I1: AGOSTO | J1: SEPTIEMBRE | K1: OCTUBRE | L1: NOVIEMBRE | M1: DICIEMBRE
A2: Nafta | B2: 16000 | C2: 20000 | D2: 20000
A3: PEAJE | D3: =5000+3100+3100+450 -> 11650
A4: Nafta | E4: 10000
A5: SEGURO MOTO | B5: 12700 | C5: 12700 | D5: 12700 | E5: 12700 | F5: 12700 | G5: 12700 | I5: 13358
A6: Nafta | I6: 20000
A7: NAFTA 21-08 | I7: 10000
A8: Chapa patente | I8: 10000
A9: Nafta 29-08 | I9: 10000
A10: NAFTA | J10: 10000
A11: NAFTA | J11: 40000
A12: NAFTA | K12: 10000
A13: NAFTA | L13: 15000
A121: TOTAL | B121: =+SUM(B2:B120) -> 28700 | C121: =+SUM(C2:C120) -> 32700 | D121: =+SUM(D2:D120) -> 44350 | E121: =+SUM(E2:E120) -> 22700 | F121: =+SUM(F2:F120) -> 12700 | G121: =+SUM(G2:G120) -> 12700 | H121: =+SUM(H2:H120) -> 0 | I121: =+SUM(I2:I120) -> 63358 | ... M121: =+SUM(M2:M120) -> 0

Sheet IMPUESTOS
A1: ITEM | B1: ENERO | C1: FEBRERO | D1: MARZO | E1: ABRIL | F1: MAYO | G1: JUNIO | H1: JULIO | I1: AGOSTO | J1: SEPTIEMBRE | K1: OCTUBRE | L1: NOVIEMBRE | M1: DICIEMBRE
A2: EDESUR 302796 | E2: 22518 | F2: 32208.81 | G2: 33242 | I2: 78125 | K2: 70000 | L2: 70000
A3: ABL part 2811590 | E3: 11000 | F3: 12331.67 | G3: 6823 | I3: 12813 | J3: 11280 | K3: 20000 | L3: 20000
A4: INTERNET $20846 (CLAVE Airampos12+) | E4: 0 | I4: 20846 | K4: 25000 | L4: 25000
A5: AYSA 7932 | E5: 30992 | F5: 31292 | G5: 31605 | I5: 32219 | K5: 36000 | L5: 36000
E6: -
A121: TOTAL | B121: =+SUM(B2:B120) -> 0 | C121: =+SUM(C2:C120) -> 0 | D121: =+SUM(D2:D120) -> 0 | E121: =+SUM(E2:E120) -> 64510 | F121: =+SUM(F2:F120) -> 75832.48 | G121: =+SUM(G2:G120) -> 71670 | H121: =+SUM(H2:H120) -> 0 | I121: =+SUM(I2:I120) -> 144003 | ... M121: =+SUM(M2:M120) -> 0

Sheet TAXI SALIDAS
A1: ITEM | B1: ENERO | C1: FEBRERO | D1: MARZO | E1: ABRIL | F1: MAYO | G1: JUNIO | H1: JULIO | I1: AGOSTO | J1: SEPTIEMBRE | K1: OCTUBRE | L1: NOVIEMBRE | M1: DICIEMBRE
A121: TOTAL | B121: =+SUM(B2:B120) -> 0 | C121: =+SUM(C2:C120) -> 0 | D121: =+SUM(D2:D120) -> 0 | E121: =+SUM(E2:E120) -> 0 | F121: =+SUM(F2:F120) -> 0 | G121: =+SUM(G2:G120) -> 0 | H121: =+SUM(H2:H120) -> 0 | I121: =+SUM(I2:I120) -> 0 | ... M121: =+SUM(M2:M120) -> 0

Sheet TELEFONIA
A1: ITEM | B1: ENERO | C1: FEBRERO | D1: MARZO | E1: ABRIL | F1: MAYO | G1: JUNIO | H1: JULIO | I1: AGOSTO | J1: SEPTIEMBRE | K1: OCTUBRE | L1: NOVIEMBRE | M1: DICIEMBRE
A2: Celular | B2: 12000 | C2: 12000 | D2: 14000
A3: Celular | E3: =6200 -> 6200
A4: Celular | E4: 12000
A5: Celular | I5: 13000 | J5: 14000 | K5: 14000
A89: TOTAL | B89: =+SUM(B2:B88) -> 12000 | C89: =+SUM(C2:C88) -> 12000 | D89: =+SUM(D2:D88) -> 14000 | E89: =+SUM(E2:E88) -> 18200 | F89: =+SUM(F2:F88) -> 0 | G89: =+SUM(G2:G88) -> 0 | H89: =+SUM(H2:H88) -> 0 | I89: =+SUM(I2:I88) -> 13000 | ... M89: =+SUM(M2:M88) -> 0

Sheet DIMITRI
A1: ITEM | B1: ENERO | C1: FEBRERO | D1: MARZO | E1: ABRIL | F1: MAYO | G1: JUNIO | H1: JULIO | I1: AGOSTO | J1: SEPTIEMBRE | K1: OCTUBRE | L1: NOVIEMBRE | M1: DICIEMBRE
A2: Dimi | B2: 60000 | C2: 60000 | D2: 65000 | E2: 65000
A3: UBER DIMI | E3: 45000
A4: SALSA DIMI | E4: 6500
A5: Dimi | K5: 31500
A121: TOTAL | B121: =+SUM(B2:B120) -> 60000 | C121: =+SUM(C2:C120) -> 60000 | D121: =+SUM(D2:D120) -> 65000 | E121: =+SUM(E2:E120) -> 116500 | F121: =+SUM(F2:F120) -> 0 | G121: =+SUM(G2:G120) -> 0 | H121: =+SUM(H2:H120) -> 0 | I121: =+SUM(I2:I120) -> 0 | ... M121: =+SUM(M2:M120) -> 0

Sheet ROPA
A1: ITEM | B1: ENERO | C1: FEBRERO | D1: MARZO | E1: ABRIL | F1: MAYO | G1: JUNIO | H1: JULIO | I1: AGOSTO | J1: SEPTIEMBRE | K1: OCTUBRE | L1: NOVIEMBRE | M1: DICIEMBRE
A89: TOTAL | B89: =+SUM(B2:B88) -> 0 | C89: =+SUM(C2:C88) -> 0 | D89: =+SUM(D2:D88) -> 0 | E89: =+SUM(E2:E88) -> 0 | F89: =+SUM(F2:F88) -> 0 | G89: =+SUM(G2:G88) -> 0 | H89: =+SUM(H2:H88) -> 0 | I89: =+SUM(I2:I88) -> 0 | ... M89: =+SUM(M2:M88) -> 0

Sheet EQUIPAMIENTO
A1: ITEM | B1: ENERO | C1: FEBRERO | D1: MARZO | E1: ABRIL | F1: MAYO | G1: JUNIO | H1: JULIO | I1: AGOSTO | J1: SEPTIEMBRE | K1: OCTUBRE | L1: NOVIEMBRE | M1: DICIEMBRE
A2: COLCHON | E2: 146000
A3: SABANAS | E3: 53000
A4: CUADERNO INTELIGENTE | F4: 65000
A5: MICROFONO | F5: 25000
A6: PLATOS Y CUBIERTOS | G6: 15500
A7: SOGA DEPORTE | G7: 8000
A8: SABANAS | G8: 20000
A9: REPARCION MOTO | J9: =82000+19080 -> 101080
A89: TOTAL | B89: =+SUM(B2:B88) -> 0 | C89: =+SUM(C2:C88) -> 0 | D89: =+SUM(D2:D88) -> 0 | E89: =+SUM(E2:E88) -> 199000 | F89: =+SUM(F2:F88) -> 90000 | G89: =+SUM(G2:G88) -> 43500 | H89: =+SUM(H2:H88) -> 0 | I89: =+SUM(I2:I88) -> 0 | ... M89: =+SUM(M2:M88) -> 0

Sheet LIMP &HIGUIENE
A1: ITEM | B1: ENERO | C1: FEBRERO | D1: MARZO | E1: ABRIL | F1: MAYO | G1: JUNIO | H1: JULIO | I1: AGOSTO | J1: SEPTIEMBRE | K1: OCTUBRE | L1: NOVIEMBRE | M1: DICIEMBRE
A2: LAVADERO | D2: 12000 | E2: 12000
A3: PELO | F3: 33000
A4: PELO | G4: =3505.5+6997.5 -> 10503
A5: CREMA TATTOO | G5: 15000
A89: TOTAL | B89: =+SUM(B2:B88) -> 0 | C89: =+SUM(C2:C88) -> 0 | D89: =+SUM(D2:D88) -> 12000 | E89: =+SUM(E2:E88) -> 12000 | F89: =+SUM(F2:F88) -> 33000 | G89: =+SUM(G2:G88) -> 25503 | H89: =+SUM(H2:H88) -> 0 | I89: =+SUM(I2:I88) -> 0 | ... M89: =+SUM(M2:M88) -> 0

Sheet PSICOLOGO
A1: ITEM | B1: ENERO | C1: FEBRERO | D1: MARZO | E1: ABRIL | F1: MAYO | G1: JUNIO | H1: JULIO | I1: AGOSTO | J1: SEPTIEMBRE | K1: OCTUBRE | L1: NOVIEMBRE | M1: DICIEMBRE
A89: TOTAL | B89: =+SUM(B2:B88) -> 0 | C89: =+SUM(C2:C88) -> 0 | D89: =+SUM(D2:D88) -> 0 | E89: =+SUM(E2:E88) -> 0 | F89: =+SUM(F2:F88) -> 0 | G89: =+SUM(G2:G88) -> 0 | H89: =+SUM(H2:H88) -> 0 | I89: =+SUM(I2:I88) -> 0 | ... M89: =+SUM(M2:M88) -> 0

Sheet DEPORTE
A1: ITEM | B1: ENERO | C1: FEBRERO | D1: MARZO | E1: ABRIL | F1: MAYO | G1: JUNIO | H1: JULIO | I1: AGOSTO | J1: SEPTIEMBRE | K1: OCTUBRE | L1: NOVIEMBRE | M1: DICIEMBRE
A2: GYM | B2: 45000 | C2: 45000 | D2: 30000 | G2: 36000
A3: PROTEINAS | B3: 45000 | C3: 45000 | D3: 45000 | E3: =45000+64000 -> 109000 | G3: 50000
A4: PREENTRENO | B4: 25000 | C4: 25000 | D4: 25000
A5: VITAMINAS | B5: 40000 | C5: 40000 | D5: 40000 | G5: 45000
A6: LCARNITINA | G6: 17000
A7: GYM NICO | G7: 16000
A8: GYM | G8: 36000
A9: VITAMINAS Y PREENTRENO | I9: 79000
A10: GYM | I10: 39000
A11: PROTEINAS | I11: 42000
A12: Magnesio | I12: 10000
A89: TOTAL | B89: =+SUM(B2:B88) -> 155000 | C89: =+SUM(C2:C88) -> 155000 | D89: =+SUM(D2:D88) -> 140000 | E89: =+SUM(E2:E88) -> 109000 | F89: =+SUM(F2:F88) -> 0 | G89: =+SUM(G2:G88) -> 200000 | H89: =+SUM(H2:H88) -> 0 | I89: =+SUM(I2:I88) -> 170000 | ... M89: =+SUM(M2:M88) -> 0

Sheet YOGA
A1: ITEM | B1: ENERO | C1: FEBRERO | D1: MARZO | E1: ABRIL | F1: MAYO | G1: JUNIO | H1: JULIO | I1: AGOSTO | J1: SEPTIEMBRE | K1: OCTUBRE | L1: NOVIEMBRE | M1: DICIEMBRE
A89: TOTAL | B89: =+SUM(B2:B88) -> 0 | C89: =+SUM(C2:C88) -> 0 | D89: =+SUM(D2:D88) -> 0 | E89: =+SUM(E2:E88) -> 0 | F89: =+SUM(F2:F88) -> 0 | G89: =+SUM(G2:G88) -> 0 | H89: =+SUM(H2:H88) -> 0 | I89: =+SUM(I2:I88) -> 0 | ... M89: =+SUM(M2:M88) -> 0

Sheet EDUCACION
A1: ITEM | B1: ENERO | C1: FEBRERO | D1: MARZO | E1: ABRIL | F1: MAYO | G1: JUNIO | H1: JULIO | I1: AGOSTO | J1: SEPTIEMBRE | K1: OCTUBRE | L1: NOVIEMBRE | M1: DICIEMBRE
A89: TOTAL | B89: =+SUM(B2:B88) -> 0 | C89: =+SUM(C2:C88) -> 0 | D89: =+SUM(D2:D88) -> 0 | E89: =+SUM(E2:E88) -> 0 | F89: =+SUM(F2:F88) -> 0 | G89: =+SUM(G2:G88) -> 0 | H89: =+SUM(H2:H88) -> 0 | I89: =+SUM(I2:I88) -> 0 | ... M89: =+SUM(M2:M88) -> 0

Sheet AYUDA A OTROS
A1: ITEM | B1: ENERO | C1: FEBRERO | D1: MARZO | E1: ABRIL | F1: MAYO | G1: JUNIO | H1: JULIO | I1: AGOSTO | J1: SEPTIEMBRE | K1: OCTUBRE | L1: NOVIEMBRE | M1: DICIEMBRE
A121: TOTAL | B121: =+SUM(B2:B120) -> 0 | C121: =+SUM(C2:C120) -> 0 | D121: =+SUM(D2:D120) -> 0 | E121: =+SUM(E2:E120) -> 0 | F121: =+SUM(F2:F120) -> 0 | G121: =+SUM(G2:G120) -> 0 | H121: =+SUM(H2:H120) -> 0 | I121: =+SUM(I2:I120) -> 0 | ... M121: =+SUM(M2:M120) -> 0

Sheet MEDICOS
A1: ITEM | B1: ENERO | C1: FEBRERO | D1: MARZO | E1: ABRIL | F1: MAYO | G1: JUNIO | H1: JULIO | I1: AGOSTO | J1: SEPTIEMBRE | K1: OCTUBRE | L1: NOVIEMBRE | M1: DICIEMBRE
A2: ANTIPARASITARIOS | E2: 13770
A3: AMOXICILINA | I3: 22000
A4: PEDICURA | K4: =25000 -> 25000
A5: FARMACIA | K5: 7000
A89: TOTAL | B89: =+SUM(B2:B88) -> 0 | C89: =+SUM(C2:C88) -> 0 | D89: =+SUM(D2:D88) -> 0 | E89: =+SUM(E2:E88) -> 13770 | F89: =+SUM(F2:F88) -> 0 | G89: =+SUM(G2:G88) -> 0 | H89: =+SUM(H2:H88) -> 0 | I89: =+SUM(I2:I88) -> 22000 | ... M89: =+SUM(M2:M88) -> 0

Sheet SALIDA CHICAS
A1: ITEM | B1: ENERO | C1: FEBRERO | D1: MARZO | E1: ABRIL | F1: MAYO | G1: JUNIO | H1: JULIO | I1: AGOSTO | J1: SEPTIEMBRE | K1: OCTUBRE | L1: NOVIEMBRE | M1: DICIEMBRE
A2: CITA ROMANTICA | E2: =+32000+43000+20000+25000+23000 -> 143000
A3: CITA ROMANTICA | E3: 40000
A4: PERICO AISHA | E4: 22674
A89: TOTAL | B89: =+SUM(B2:B88) -> 0 | C89: =+SUM(C2:C88) -> 0 | D89: =+SUM(D2:D88) -> 0 | E89: =+SUM(E2:E88) -> 205674 | F89: =+SUM(F2:F88) -> 0 | G89: =+SUM(G2:G88) -> 0 | H89: =+SUM(H2:H88) -> 0 | I89: =+SUM(I2:I88) -> 0 | ... M89: =+SUM(M2:M88) -> 0

Sheet SALIDA AMIGOS
A1: ITEM | B1: ENERO | C1: FEBRERO | D1: MARZO | E1: ABRIL | F1: MAYO | G1: JUNIO | H1: JULIO | I1: AGOSTO | J1: SEPTIEMBRE | K1: OCTUBRE | L1: NOVIEMBRE | M1: DICIEMBRE
A89: TOTAL | B89: =+SUM(B2:B88) -> 0 | C89: =+SUM(C2:C88) -> 0 | D89: =+SUM(D2:D88) -> 0 | E89: =+SUM(E2:E88) -> 0 | F89: =+SUM(F2:F88) -> 0 | G89: =+SUM(G2:G88) -> 0 | H89: =+SUM(H2:H88) -> 0 | I89: =+SUM(I2:I88) -> 0 | ... M89: =+SUM(M2:M88) -> 0

Sheet APPS
A1: ITEM | B1: ENERO | C1: FEBRERO | D1: MARZO | E1: ABRIL | F1: MAYO | G1: JUNIO | H1: JULIO | I1: AGOSTO | J1: SEPTIEMBRE | K1: OCTUBRE | L1: NOVIEMBRE | M1: DICIEMBRE
A2: ADRI KASTEL | B2: =19*1360 -> 25840 | C2: =19*1360 -> 25840 | D2: =19*1360 -> 25840 | E2: =19*1360 -> 25840
A3: LEVANTART | E3: =9*1365 -> 12285 | F3: =9*1365 -> 12285
A4: CHAT GPT | G4: 31000
A89: TOTAL | B89: =+SUM(B2:B88) -> 25840 | C89: =+SUM(C2:C88) -> 25840 | D89: =+SUM(D2:D88) -> 25840 | E89: =+SUM(E2:E88) -> 38125 | F89: =+SUM(F2:F88) -> 12285 | G89: =+SUM(G2:G88) -> 31000 | H89: =+SUM(H2:H88) -> 0 | I89: =+SUM(I2:I88) -> 0 | ... M89: =+SUM(M2:M88) -> 0

Sheet VACACIONES
A1: ITEM | B1: ENERO | C1: FEBRERO | D1: MARZO | E1: ABRIL | F1: MAYO | G1: JUNIO | H1: JULIO | I1: AGOSTO | J1: SEPTIEMBRE | K1: OCTUBRE | L1: NOVIEMBRE | M1: DICIEMBRE
A89: TOTAL | B89: =+SUM(B2:B88) -> 0 | C89: =+SUM(C2:C88) -> 0 | D89: =+SUM(D2:D88) -> 0 | E89: =+SUM(E2:E88) -> 0 | F89: =+SUM(F2:F88) -> 0 | G89: =+SUM(G2:G88) -> 0 | H89: =+SUM(H2:H88) -> 0 | I89: =+SUM(I2:I88) -> 0 | ... M89: =+SUM(M2:M88) -> 0
